Workbook

Sheet Sprachversionen
A1: AED | B1: deutsch | C1: F I N A N Z B E R I C H T | D1: ÜBERSICHT ÜBER EINNAHMEN UND AUSGABEN | E1: Projektnummer | F1: Projektlaufzeit | G1: Aktueller Berichtszeitraum | H1: von (TT MM JJJJ): | I1: bis (TT MM JJJJ): | J1: EINNAHMEN | K1: (in lokaler Währung) | L1: Bewilligtes Budget | M1: Einnahmen im Berichtszeitraum | N1: Einnahmen der gesamten Projektlaufzeit | O1: % erhaltene Einnahmen | P1: Begründung der Budgetüber- oder unterschreitung | Q1: Saldovortrag (aus vorherigem Berichtszeitraum) | R1: Lokale Eigenleistung | S1: Beiträge von dritter Seite | T1: KMW Mittel* | U1: Zinserträge | V1: GESAMT | W1: Datum | X1: Rate | Y1: AUSGABEN | Z1: Ausgaben im Berichtszeitraum | AA1: Projekttitel | AB1: Sprache | AC1: Lokalwährung | AD1: Bauausgaben | AE1: Zwischensumme Bauausgaben | AF1: Einmalige Ausgaben (Investitionen) | AG1: Zwischensumme Einmalige Ausgaben (Investitionen) | AH1: Personalkosten | AI1: Zwischensumme Personalkosten | AJ1: Laufende Ausgaben für Projektaktivitäten | AK1: Zwischensumme Laufende Ausgaben für Projektaktivitäten | AL1: Projektverwaltung | AM1: Zwischensumme Projektverwaltung | AN1: Evaluierung | AO1: Audit | AP1: Reserve - nur nach Genehmigung | AQ1: Summe | AR1: ABSCHLUSS | AS1: Saldo für den Berichtszeitraum | AT1: Saldo (Einnahmen minus Ausgaben) | AU1: Saldenabstimmung: | AV1: Bank | AW1: Kasse | AX1: Sonstiges (noch nicht eingelöste Schecks, Vorschüsse, Darlehen, etc.) | AY1: Ich/Wir bestätige/n die Richtigkeit des vorliegenden Berichts unter Einhaltung des von beiden Partnern unterzeichneten Projektvertrages. | AZ1: Ort, Datum Unterschrift des Projektverantwortlichen | BA1: Unterschrift einer weiteren autorisierten Person | BB1: Funktion in der Organisation: | BC1: Ich/Wir bestätige/n, dass die lokale Eigenleistung monetär ist. | BD1: Ausgaben der gesamten Projektlaufzeit | BE1: % verwendetes Budget | BF1: Wechselkurs | BG1: WK | BH1: Ausfüllbare Felder sind in den Farben links | BI1: Tipp: | BJ1: Bitte nutzen Sie zum ausfüllen des Finanzberichts unsere Ausfüllhilfe auf unserer Webseite: | BK1: https://www.kindermissionswerk.org/fuer-partner/service
A2: AFN | B2: english | C2: F I N A N C I A L R E P O R T | D2: OVERVIEW - INCOME AND EXPENDITURE | E2: Project Number | F2: Project Duration | G2: Actual Reporting Period | H2: From (DD.MM.YYYY) | I2: To (DD.MM.YYYY) | J2: INCOME | K2: (In Local Currency) | L2: Approved Budget | M2: Income During Reporting Period | N2: Total project Income (Till date) | O2: % Income received | P2: Justification of budget surplus or deficit | Q2: Balance - carried forward from previous reporting period | R2: Local Contribution | S2: Third Party Contribution | T2: KMW Funds* | U2: Interest gains | V2: Total | W2: Date | X2: Installment | Y2: EXPENSES | Z2: Expenses in Reporting Period | AA2: Project Title | AB2: Language | AC2: Local Currrency | AD2: Building Expenses | AE2: Subtotal Building Expenses | AF2: Non-Recurring Expenses (Investments) | AG2: Subtotal Non Recurring Expenses (Investments) | AH2: Personnel Expenses | AI2: Subtotal Personnel Expenses | AJ2: Ongoing Expenses for Project Activities | AK2: Subtotal Ongoing Expenses for Project Activities | AL2: Project Administration | AM2: Subtotal Project Administration | AN2: Evaluation | AO2: Audit | AP2: Contingency reserve - after authorisation only | AQ2: Total | AR2: Summary | AS2: Balance for the Reporting Period | AT2: Balance (Income Minus Expenses) | AU2: Balance Reconciliation | AV2: Bank | AW2: Cash | AX2: Others (Uncashed Cheque, advances, loans etc.) | AY2: I/We confirm the accuracy of this report in compliance with the project contract signed by both partners. | AZ2: Place, date Signature of the person responsible for the project | BA2: Signature of another authorized person | BB2: Function within the organization: | BC2: I/We confirm that the local contribution is monetary. | BD2: Total Project Expenditure | BE2: % Used Budget | BF2: Exchange Rate | BG2: ER | BH2: Fillable fields are in the colours on the left | BI2: Tip: | BJ2: Please use our completion guide on our website to fill out the financial report. | BK2: https://www.kindermissionswerk.org/en/partners/service
A3: ALL | B3: français | C3: R A P P O R T F I N A N C I E R | D3: APERÇU DES RECETTES ET DÉPENSES | E3: Numéro du projet | F3: Durée totale du projet | G3: Période actuelle couverte par le rapport | H3: de (JJ/MM/AAAA) : | I3: de (JJ/MM/AAAA) : | J3: RECETTES | K3: (en monnaie locale) | L3: Budget apprové | M3: Recettes pendant la période du rapport | N3: Cumul recettes sur toute la période | O3: % des recettes perçues | P3: Explication du dépassement de budget | Q3: Solde (de la période précédente) | R3: Apport local | S3: Contributions de tiers | T3: Fonds KMW* | U3: Intérêts bancaires | V3: TOTAL | W3: Date | X3: versement | Y3: DÉPENSES | Z3: Dépenses pendant la période du rapport | AA3: Titre du projet | AB3: Langue | AC3: Monnaie locale | AD3: Dépenses de construction | AE3: Sous-total dépenses de construction | AF3: Dépenses uniques (investissements) | AG3: Sous-total dépenses uniques (investissements) | AH3: Personnel | AI3: Sous-total personnel | AJ3: Dépenses courantes pour activités de projet | AK3: Sous-total dépenses courantes pour activités de projet | AL3: Gestion de projet | AM3: Sous-total gestion de projet | AN3: Evaluation | AO3: Audit | AP3: Réserve - uniquement après accord | AQ3: TOTAL | AR3: CLÔTURE DES COMPTES | AS3: Solde à la fin de la période du rapport | AT3: Solde (recettes moins dépenses) | AU3: Rapprochement des soldes : | AV3: Banque | AW3: Caisse | AX3: Divers (chèques non encaissés, avances, prêts, etc.) | AY3: Je confirme / Nous certifions que le présent rapport est exact et conforme au contrat de projet signé par les deux partenaires. | AZ3: Lieu, date Signature du responsable du projet | BA3: Signature d’une autre personne autorisée | BB3: Fonction au sein de l’organisation : | BC3: Je confirme / Nous confirmons que l'apport local est monétaire. | BD3: Cumul dépenses sur toute la période | BE3: % budget consommé | BF3: Taux de change | BG3: TC | BH3: Les champs remplissables sont dans les couleurs à gauche | BI3: Astuce : | BJ3: Veuillez utiliser notre aide à la saisie disponible sur notre site web pour remplir le rapport financier: | BK3: https://www.kindermissionswerk.org/fr/pour-les-partenaires/services
A4: AMD | B4: español | C4: I N F O R M E F I N A N C I E R O | D4: Resumen de los ingresos y egresos | E4: Número del proyecto | F4: Duración del proyecto | G4: Período de referencia | H4: de (DD MM AAAA): | I4: hasta (DD MM AAAA) | J4: Ingresos | K4: (en moneda local) | L4: Presupuesto aprobado | M4: Ingresos del período de referencia | N4: Ingresos acumulados (total desde el início) | O4: % Ingresos recibidos | P4: Justificación del superávit / déficit presupuestario | Q4: Saldo (procendente del período de referencia anterior) | R4: Aporte propio | S4: Aportes de terceros | T4: Fondos KMW * | U4: Intereses acreedores percibidos | V4: TOTAL | W4: Fecha | X4: Cuota | Y4: EGRESOS | Z4: Egresos del período de referencia | AA4: Título del proyecto | AB4: Idioma | AC4: Moneda local | AD4: Gastos de construcción | AE4: Subtotal gastos de construcción | AF4: Gastos extraordinarios (inversiones) | AG4: Subtotal gastos extraorinarios (inversiones) | AH4: Gastos de personal | AI4: Subtotal gastos de personal | AJ4: Gastos corrientes para actividades del proyecto | AK4: Subtotal gastos corrientes para actividades | AL4: Gastos administrativos del proyecto / Gestión del proyecto | AM4: Subtotal gastos administrativos del proyecto | AN4: Evaluación | AO4: Auditoría externa | AP4: Reserva - solo previa autorización | AQ4: Total | AR4: CIERRE DE CUENTAS | AS4: Saldo en el período de referencia | AT4: Saldo (ingresos menos egresos) | AU4: Conciliación de saldos | AV4: Banco | AW4: Caja | AX4: Otros (cheques aún no cobrados, anticipos, créditos, etc.) | AY4: Por la presente certifico/certificamos la corrección del presente informe, el cual cumple las disposiciones del contrato de proyecto | AZ4: Lugar, fecha, firma del resonsable de proyecto | BA4: Firma de otra persona autorizada | BB4: Cargo o Función dentro de la organización: | BC4: Confirmo/confirmamos que el aporte propio es monetario | BD4: Egresos acumulados desde el início del proyecto | BE4: Ejecución presupuestaria (en %) | BF4: Tipo de cambio | BG4: TC | BH4: Los campos rellenables aparecen en los colores de la izquierda | BI4: Consejo: | BJ4: Por favor, utilice nuestra guía para completar el informe financiero, disponible en nuestro sitio web: | BK4: https://www.kindermissionswerk.org/es/para-contrapartes-de-proyectos/servicios
A5: ANG | B5: português | C5: RELATÓRIO FINANCEIRO | D5: Resumo das receitas e despesas | E5: Número do projeto | F5: Duração do projeto | G5: Período de referência | H5: de (DD MM AAAA): | I5: até (DD MM AAAA): | J5: RECEITAS | K5: (em moeda local) | L5: Plano de custos e financiamento aprovado | M5: Receitas do período de referência | N5: Receitas cumuladas (total desde o início) | O5: % Reiceitas recebidas | P5: Justificação do superávit / déficit orçamentário | Q5: Saldo transportado (do período de referência anterior) | R5: Contribuição própria | S5: Contribuções de terceiros | T5: Subsídio KMW * | U5: Juros credores auferidos | V5: TOTAL | W5: Data | X5: transferência parcial | Y5: DESPESAS | Z5: Despesas do período de referência | AA5: Título do projeto | AB5: Idioma | AC5: Moeda local | AD5: Despesas de construção (civil) | AE5: Subtotal despesas de construção (civil) | AF5: Despesas únicas (investimentos) | AG5: Subtotal Despesas únicas (investimentos) | AH5: Despesas com pessoal / recursos humanos | AI5: Subtotal Despesas com pessoal / recursos humanos | AJ5: Custos de atividades de projeto | AK5: Subtotal Custos de atividades de projeto | AL5: Administração do projeto | AM5: Subtotal Administração do projeto | AN5: Avaliação | AO5: Auditoria externa | AP5: Reserva - somente após autorização | AQ5: Total | AR5: BALANÇO | AS5: Saldo do período de referência | AT5: Saldo (receitas menos despesas | AU5: Conciliação de saldo | AV5: Banco | AW5: Caixa | AX5: Outros (cheques não descontados, adiantamentos, empréstimos, etc.). | AY5: Declaro/declaramos a veracidade deste relatório em conformidade com o contrato firmado entre as partes. | AZ5: Local, data e assinatura do responsável do projeto | BA5: Assinatura de uma outra pessoa devidamente autorizada | BB5: Função / cargo na organização: | BC5: Confirmo/confirmamos que a contribuição prória é monetária | BD5: Despesas acumuladas desde o início de projeto | BE5: Execução orçamentária (em %) | BF5: Taxa de câmbio | BG5: TC | BH5: Os campos preenchíveis estão nas cores à esquerda | BI5: Dica: | BJ5: Por favor, utilize nosso guia de preenchimento disponível em nosso site para preencher o relatório financeiro: | BK5: https://www.kindermissionswerk.org/pt/para-os-parceiros/servico
A6: AOA
A7: ARS
A8: AUD
A9: AWG
A10: AZN
A11: BAM
A12: BBD
A13: BDT
A14: BGN
A15: BHD
A16: BIF
A17: BMD
... A153: ZWL

Sheet Financial Report
B1: =IF($E$2="","",VLOOKUP($E$2,Sprachversionen!$B:$BN,2,FALSE)) -> 0 | J1: =IF($E$2="","",VLOOKUP($E$2,Sprachversionen!$B:$BN,60,FALSE)) -> 0
B2: _en | D2: =IF($E$2="","Chose your language",VLOOKUP($E$2,Sprachversionen!$B:$BN,27,FALSE)) -> 0 | E2: english | J2: =IF($E$2="","",VLOOKUP($E$2,Sprachversionen!$B:$BN,61,FALSE)) -> 0
B3: =IF($E$2="","",VLOOKUP($E$2,Sprachversionen!$B:$BN,3,FALSE)) -> 0 | D3: =IF($E$2="","",VLOOKUP($E$2,Sprachversionen!$B:$BN,28,FALSE)) -> 0
J4: =HYPERLINK(VLOOKUP($E$2,Sprachversionen!$B:$BN,62,FALSE)) -> 0
B5: =IF($E$2="","",VLOOKUP($E$2,Sprachversionen!$B:$BN,4,FALSE)) -> 0
B6: =IF($E$2="","",VLOOKUP($E$2,Sprachversionen!$B:$BN,26,FALSE)) -> 0
B8: =IF($E$2="","",VLOOKUP($E$2,Sprachversionen!$B:$BN,5,FALSE)) -> 0 | D8: =IF($E$2="","",VLOOKUP($E$2,Sprachversionen!$B:$BN,7,FALSE)) -> 0 | F8: =IF($E$2="","",VLOOKUP($E$2,Sprachversionen!$B:$BN,8,FALSE)) -> 0 | K8: =IF($E$2="","",VLOOKUP($E$2,Sprachversionen!$B:$BN,59,FALSE)) -> 0
B9: =IF($E$2="","",VLOOKUP($E$2,Sprachversionen!$B:$BN,6,FALSE)) -> 0 | D9: =D8 -> 0 | F9: =F8 -> 0
D11: =IF($E$2="","",VLOOKUP($E$2,Sprachversionen!$B:$BN,11,FALSE)) -> 0 | E11: =IF($E$2="","",VLOOKUP($E$2,Sprachversionen!$B:$BN,12,FALSE)) -> 0 | F11: =IF($E$2="","",VLOOKUP($E$2,Sprachversionen!$B:$BN,13,FALSE)) -> 0 | G11: =IF($E$2="","",VLOOKUP($E$2,Sprachversionen!$B:$BN,14,FALSE)) -> 0 | H11: =IF($E$2="","",VLOOKUP($E$2,Sprachversionen!$B:$BN,15,FALSE)) -> 0 | J11: =B18 -> 0 | Q11: =B18 -> 0
B12: =IF($E$2="","",VLOOKUP($E$2,Sprachversionen!$B:$BN,9,FALSE)) -> 0
B13: =IF($E$2="","",VLOOKUP($E$2,Sprachversionen!$B:$BN,10,FALSE)) -> 0 | L13: =IF($E$2="","",VLOOKUP($E$2,Sprachversionen!$B:$BN,22,FALSE)) -> 0 | M13: Euro | N13: =IF(E3="",VLOOKUP($E$2,Sprachversionen!$B:$BN,28,FALSE),E3) -> 0 | O13: =IF($E$2="","",VLOOKUP($E$2,Sprachversionen!$B:$BN,58,FALSE)) -> 0 | S13: =IF($E$2="","",VLOOKUP($E$2,Sprachversionen!$B:$BN,22,FALSE)) -> 0 | T13: Euro | U13: =IF(E3="",VLOOKUP($E$2,Sprachversionen!$B:$BN,28,FALSE),E3) -> 0 | V13: =IF($E$2="","",VLOOKUP($E$2,Sprachversionen!$B:$BN,58,FALSE)) -> 0
J14: 1. | K14: =IF($E$2="","",VLOOKUP($E$2,Sprachversionen!$B:$BN,23,FALSE)) -> 0 | O14: =IFERROR(INDEX($N$1:$N$31,ROW())/INDEX($M$1:$M$31,ROW()),"") -> 0 | Q14: 19. | R14: =IF($E$2="","",VLOOKUP($E$2,Sprachversionen!$B:$BN,23,FALSE)) -> 0 | V14: =IFERROR(INDEX($U$1:$U$31,ROW())/INDEX($T$1:$T$31,ROW()),"") -> 0
B15: =IF($E$2="","",VLOOKUP($E$2,Sprachversionen!$B:$BN,16,FALSE)) -> 0 | J15: 2. | K15: =IF($E$2="","",VLOOKUP($E$2,Sprachversionen!$B:$BN,23,FALSE)) -> 0 | O15: =IFERROR(INDEX($N$1:$N$31,ROW())/INDEX($M$1:$M$31,ROW()),"") -> 0 | Q15: 20. | R15: =IF($E$2="","",VLOOKUP($E$2,Sprachversionen!$B:$BN,23,FALSE)) -> 0 | V15: =IFERROR(INDEX($U$1:$U$31,ROW())/INDEX($T$1:$T$31,ROW()),"") -> 0
B16: =IF($E$2="","",VLOOKUP($E$2,Sprachversionen!$B:$BN,17,FALSE)) -> 0 | D16: 0 | G16: =IFERROR(INDEX($F$1:$F$1001,ROW())/INDEX($D$1:$D$1001,ROW()),0) -> 0 | J16: 3. | K16: =IF($E$2="","",VLOOKUP($E$2,Sprachversionen!$B:$BN,23,FALSE)) -> 0 | O16: =IFERROR(INDEX($N$1:$N$31,ROW())/INDEX($M$1:$M$31,ROW()),"") -> 0 | Q16: 21. | R16: =IF($E$2="","",VLOOKUP($E$2,Sprachversionen!$B:$BN,23,FALSE)) -> 0 | V16: =IFERROR(INDEX($U$1:$U$31,ROW())/INDEX($T$1:$T$31,ROW()),"") -> 0
B17: =IF($E$2="","",VLOOKUP($E$2,Sprachversionen!$B:$BN,18,FALSE)) -> 0 | D17: 0 | G17: =IFERROR(INDEX($F$1:$F$1001,ROW())/INDEX($D$1:$D$1001,ROW()),0) -> 0 | J17: 4. | K17: =IF($E$2="","",VLOOKUP($E$2,Sprachversionen!$B:$BN,23,FALSE)) -> 0 | O17: =IFERROR(INDEX($N$1:$N$31,ROW())/INDEX($M$1:$M$31,ROW()),"") -> 0 | Q17: 22. | R17: =IF($E$2="","",VLOOKUP($E$2,Sprachversionen!$B:$BN,23,FALSE)) -> 0 | V17: =IFERROR(INDEX($U$1:$U$31,ROW())/INDEX($T$1:$T$31,ROW()),"") -> 0
B18: =IF($E$2="","",VLOOKUP($E$2,Sprachversionen!$B:$BN,19,FALSE)) -> 0 | D18: 0 | G18: =IFERROR(INDEX($F$1:$F$1001,ROW())/INDEX($D$1:$D$1001,ROW()),0) -> 0 | J18: 5. | K18: =IF($E$2="","",VLOOKUP($E$2,Sprachversionen!$B:$BN,23,FALSE)) -> 0 | O18: =IFERROR(INDEX($N$1:$N$31,ROW())/INDEX($M$1:$M$31,ROW()),"") -> 0 | Q18: 23. | R18: =IF($E$2="","",VLOOKUP($E$2,Sprachversionen!$B:$BN,23,FALSE)) -> 0 | V18: =IFERROR(INDEX($U$1:$U$31,ROW())/INDEX($T$1:$T$31,ROW()),"") -> 0
B19: =IF($E$2="","",VLOOKUP($E$2,Sprachversionen!$B:$BN,20,FALSE)) -> 0 | D19: 0 | G19: =IFERROR(INDEX($F$1:$F$1001,ROW())/INDEX($D$1:$D$1001,ROW()),0) -> 0 | J19: 6. | K19: =IF($E$2="","",VLOOKUP($E$2,Sprachversionen!$B:$BN,23,FALSE)) -> 0 | O19: =IFERROR(INDEX($N$1:$N$31,ROW())/INDEX($M$1:$M$31,ROW()),"") -> 0 | Q19: 24. | R19: =IF($E$2="","",VLOOKUP($E$2,Sprachversionen!$B:$BN,23,FALSE)) -> 0 | V19: =IFERROR(INDEX($U$1:$U$31,ROW())/INDEX($T$1:$T$31,ROW()),"") -> 0
B20: =IF($E$2="","",VLOOKUP($E$2,Sprachversionen!$B:$BN,21,FALSE)) -> 0 | D20: =SUMPRODUCT(ROUND(D15:D19, 2)) -> 0 | E20: =SUMPRODUCT(ROUND(E15:E19, 2)) -> 0 | F20: =SUMPRODUCT(ROUND(F15:F19, 2)) -> 0 | G20: =IFERROR(INDEX($F$1:$F$1001,ROW())/INDEX($D$1:$D$1001,ROW()),0) -> 0 | J20: 7. | K20: =IF($E$2="","",VLOOKUP($E$2,Sprachversionen!$B:$BN,23,FALSE)) -> 0 | O20: =IFERROR(INDEX($N$1:$N$31,ROW())/INDEX($M$1:$M$31,ROW()),"") -> 0 | Q20: 25. | R20: =IF($E$2="","",VLOOKUP($E$2,Sprachversionen!$B:$BN,23,FALSE)) -> 0 | V20: =IFERROR(INDEX($U$1:$U$31,ROW())/INDEX($T$1:$T$31,ROW()),"") -> 0
J21: 8. | K21: =IF($E$2="","",VLOOKUP($E$2,Sprachversionen!$B:$BN,23,FALSE)) -> 0 | O21: =IFERROR(INDEX($N$1:$N$31,ROW())/INDEX($M$1:$M$31,ROW()),"") -> 0 | Q21: 26. | R21: =IF($E$2="","",VLOOKUP($E$2,Sprachversionen!$B:$BN,23,FALSE)) -> 0 | V21: =IFERROR(INDEX($U$1:$U$31,ROW())/INDEX($T$1:$T$31,ROW()),"") -> 0
J22: 9. | K22: =IF($E$2="","",VLOOKUP($E$2,Sprachversionen!$B:$BN,23,FALSE)) -> 0 | O22: =IFERROR(INDEX($N$1:$N$31,ROW())/INDEX($M$1:$M$31,ROW()),"") -> 0 | Q22: 27. | R22: =IF($E$2="","",VLOOKUP($E$2,Sprachversionen!$B:$BN,23,FALSE)) -> 0 | V22: =IFERROR(INDEX($U$1:$U$31,ROW())/INDEX($T$1:$T$31,ROW()),"") -> 0
D23: =D11 -> 0 | E23: =IF($E$2="","",VLOOKUP($E$2,Sprachversionen!$B:$BN,25,FALSE)) -> 0 | F23: =IF($E$2="","",VLOOKUP($E$2,Sprachversionen!$B:$BN,55,FALSE)) -> 0 | G23: =IF($E$2="","",VLOOKUP($E$2,Sprachversionen!$B:$BN,56,FALSE)) -> 0 | H23: =H11 -> 0 | J23: 10. | K23: =IF($E$2="","",VLOOKUP($E$2,Sprachversionen!$B:$BN,23,FALSE)) -> 0 | O23: =IFERROR(INDEX($N$1:$N$31,ROW())/INDEX($M$1:$M$31,ROW()),"") -> 0 | Q23: 28. | R23: =IF($E$2="","",VLOOKUP($E$2,Sprachversionen!$B:$BN,23,FALSE)) -> 0 | V23: =IFERROR(INDEX($U$1:$U$31,ROW())/INDEX($T$1:$T$31,ROW()),"") -> 0
B24: =IF($E$2="","",VLOOKUP($E$2,Sprachversionen!$B:$BN,24,FALSE)) -> 0 | J24: 11. | K24: =IF($E$2="","",VLOOKUP($E$2,Sprachversionen!$B:$BN,23,FALSE)) -> 0 | O24: =IFERROR(INDEX($N$1:$N$31,ROW())/INDEX($M$1:$M$31,ROW()),"") -> 0 | Q24: 29. | R24: =IF($E$2="","",VLOOKUP($E$2,Sprachversionen!$B:$BN,23,FALSE)) -> 0 | V24: =IFERROR(INDEX($U$1:$U$31,ROW())/INDEX($T$1:$T$31,ROW()),"") -> 0
B25: =B13 -> 0 | J25: 12. | K25: =IF($E$2="","",VLOOKUP($E$2,Sprachversionen!$B:$BN,23,FALSE)) -> 0 | O25: =IFERROR(INDEX($N$1:$N$31,ROW())/INDEX($M$1:$M$31,ROW()),"") -> 0 | Q25: 30. | R25: =IF($E$2="","",VLOOKUP($E$2,Sprachversionen!$B:$BN,23,FALSE)) -> 0 | V25: =IFERROR(INDEX($U$1:$U$31,ROW())/INDEX($T$1:$T$31,ROW()),"") -> 0
J26: 13. | K26: =IF($E$2="","",VLOOKUP($E$2,Sprachversionen!$B:$BN,23,FALSE)) -> 0 | O26: =IFERROR(INDEX($N$1:$N$31,ROW())/INDEX($M$1:$M$31,ROW()),"") -> 0 | Q26: 31. | R26: =IF($E$2="","",VLOOKUP($E$2,Sprachversionen!$B:$BN,23,FALSE)) -> 0 | V26: =IFERROR(INDEX($U$1:$U$31,ROW())/INDEX($T$1:$T$31,ROW()),"") -> 0
B27: 1. | C27: =IF($E$2="","",VLOOKUP($E$2,Sprachversionen!$B:$BN,29,FALSE)) | J27: 14. | K27: =IF($E$2="","",VLOOKUP($E$2,Sprachversionen!$B:$BN,23,FALSE)) -> 0 | O27: =IFERROR(INDEX($N$1:$N$31,ROW())/INDEX($M$1:$M$31,ROW()),"") -> 0 | Q27: 32. | R27: =IF($E$2="","",VLOOKUP($E$2,Sprachversionen!$B:$BN,23,FALSE)) -> 0 | V27: =IFERROR(INDEX($U$1:$U$31,ROW())/INDEX($T$1:$T$31,ROW()),"") -> 0
B28: 1.1 | G28: =IFERROR(INDEX($F$1:$F$1001,ROW())/INDEX($D$1:$D$1001,ROW()),0) | J28: 15. | K28: =IF($E$2="","",VLOOKUP($E$2,Sprachversionen!$B:$BN,23,FALSE)) -> 0 | O28: =IFERROR(INDEX($N$1:$N$31,ROW())/INDEX($M$1:$M$31,ROW()),"") -> 0 | Q28: 33. | R28: =IF($E$2="","",VLOOKUP($E$2,Sprachversionen!$B:$BN,23,FALSE)) -> 0 | V28: =IFERROR(INDEX($U$1:$U$31,ROW())/INDEX($T$1:$T$31,ROW()),"") -> 0
B29: 1.2 | G29: =IFERROR(INDEX($F$1:$F$1001,ROW())/INDEX($D$1:$D$1001,ROW()),0) | J29: 16. | K29: =IF($E$2="","",VLOOKUP($E$2,Sprachversionen!$B:$BN,23,FALSE)) -> 0 | O29: =IFERROR(INDEX($N$1:$N$31,ROW())/INDEX($M$1:$M$31,ROW()),"") -> 0 | Q29: 34. | R29: =IF($E$2="","",VLOOKUP($E$2,Sprachversionen!$B:$BN,23,FALSE)) -> 0 | V29: =IFERROR(INDEX($U$1:$U$31,ROW())/INDEX($T$1:$T$31,ROW()),"") -> 0
B30: 1.3 | G30: =IFERROR(INDEX($F$1:$F$1001,ROW())/INDEX($D$1:$D$1001,ROW()),0) | J30: 17. | K30: =IF($E$2="","",VLOOKUP($E$2,Sprachversionen!$B:$BN,23,FALSE)) -> 0 | O30: =IFERROR(INDEX($N$1:$N$31,ROW())/INDEX($M$1:$M$31,ROW()),"") -> 0 | Q30: 35. | R30: =IF($E$2="","",VLOOKUP($E$2,Sprachversionen!$B:$BN,23,FALSE)) -> 0 | V30: =IFERROR(INDEX($U$1:$U$31,ROW())/INDEX($T$1:$T$31,ROW()),"") -> 0
B31: 1.4 | G31: =IFERROR(INDEX($F$1:$F$1001,ROW())/INDEX($D$1:$D$1001,ROW()),0) | J31: 18. | K31: =IF($E$2="","",VLOOKUP($E$2,Sprachversionen!$B:$BN,23,FALSE)) -> 0 | O31: =IFERROR(INDEX($N$1:$N$31,ROW())/INDEX($M$1:$M$31,ROW()),"") -> 0 | Q31: 36. | R31: =IF($E$2="","",VLOOKUP($E$2,Sprachversionen!$B:$BN,23,FALSE)) -> 0 | V31: =IFERROR(INDEX($U$1:$U$31,ROW())/INDEX($T$1:$T$31,ROW()),"") -> 0
B32: 1.5 | G32: =IFERROR(INDEX($F$1:$F$1001,ROW())/INDEX($D$1:$D$1001,ROW()),0)
B33: 1.6 | G33: =IFERROR(INDEX($F$1:$F$1001,ROW())/INDEX($D$1:$D$1001,ROW()),0)
B34: 1.7 | G34: =IFERROR(INDEX($F$1:$F$1001,ROW())/INDEX($D$1:$D$1001,ROW()),0)
B35: 1.8 | G35: =IFERROR(INDEX($F$1:$F$1001,ROW())/INDEX($D$1:$D$1001,ROW()),0)
B36: 1.9 | G36: =IFERROR(INDEX($F$1:$F$1001,ROW())/INDEX($D$1:$D$1001,ROW()),0)
B37: 1.10 | G37: =IFERROR(INDEX($F$1:$F$1001,ROW())/INDEX($D$1:$D$1001,ROW()),0)
B38: 1.11 | G38: =IFERROR(INDEX($F$1:$F$1001,ROW())/INDEX($D$1:$D$1001,ROW()),0)
B39: 1.12 | G39: =IFERROR(INDEX($F$1:$F$1001,ROW())/INDEX($D$1:$D$1001,ROW()),0)
B40: 1.13 | G40: =IFERROR(INDEX($F$1:$F$1001,ROW())/INDEX($D$1:$D$1001,ROW()),0)
B41: 1.14 | G41: =IFERROR(INDEX($F$1:$F$1001,ROW())/INDEX($D$1:$D$1001,ROW()),0)
B42: 1.15 | G42: =IFERROR(INDEX($F$1:$F$1001,ROW())/INDEX($D$1:$D$1001,ROW()),0)
...
